Workbook

Sheet README
B2: Manchester United · Valuation Model
B3: NYSE: MANU Roneet Khattar July 2026 Independent research, not investment advice
B5: WHY I BUILT THIS
C6: I've supported Manchester United my whole life, which means I've spent the last few years watching the club get picked apart, on the pitch and in the accounts. Somewhere in the middle of all that I noticed the share price just sitting there around $22, and nobody, not the fan channels, not the finance press, could actually tell me what was holding it up. So I built this to find out for myself. One question, stripped of all the emotion I normally watch this club with: if you ignore the badge and the history and just value the cash United generates, what is it actually worth?
B8: WHAT I FOUND
C9: On cash flows alone the club is worth roughly $4 to $5 a share. The market says $22. That gap is not the model being broken. It is everything a five year cash flow forecast cannot price: the 100,000 seat stadium in development, a 1.1 billion person fanbase, the squad as a tradeable asset, and the possibility that somebody buys the club outright at a premium. The finding that actually surprised me was how fragile the equity is. Every May, one binary outcome resets the entire valuation: Champions League or not. Miss it, and the broadcast money goes, sponsors trigger step down clauses, and the wage bill does not move because contracts are fixed. In my bear case that combination takes the equity below zero against £691.7m of net debt. That is the story of this model.
B11: HEADLINE NUMBERS
B12: DCF value | C12: $4.34 per share
B13: Market price | C13: $22.23 (17 July 2026)
B14: WACC | C14: 9.63%
B15: Beta | C15: 0.65 regressed, 0.77 adjusted
B16: Scenarios | C16: Bear -$1.26 Base $4.34 Bull $6.78
B17: Monte Carlo | C17: 1,000 runs, roughly a third end in wipeout
B19: ON THE BETA
C20: I did not want to lift a beta off a website, so I pulled two years of weekly closing prices for MANU and the S&P 500, built the return series, and ran the regression myself. Raw slope came out at 0.65. Because MANU trades only around 350,000 shares a day, thin trading suppresses the measured beta, so I applied the standard Vasicek adjustment toward the market mean and used 0.77. Every number in the WACC build follows from that.
B22: HOW THE TABS FIT TOGETHER
C23: Assumptions is the control panel. Change a blue cell there and the whole model moves. WACC Build turns the regressed beta into the 9.63% discount rate. Revenue Build projects five years, with the Champions League uplift weighted by the odds of qualifying rather than assumed forever. P&L to FCF converts revenue into cash and applies the wage feedback loop. DCF discounts the cash and bridges through net debt to a per share number. Validation, Trading Comps, Operating Comps, Sensitivity and Monte Carlo each test that number from a different direction.
B25: COLOUR KEY
C26: Blue is an input you can change. Black is a formula. Green is pulled from another tab. Yellow is a key assumption. Green fill is a reported actual from the filings.
B28: DATA
C29: Built on Manchester United's Q1 to Q3 FY2026 results, the most recent being Q3 released 27 May 2026, plus full year guidance of £655m to £665m and the confirmed third place finish. Share price, exchange rate and net debt are current as of 17 July 2026. Audited full year accounts are due around September 2026.

Sheet Quarterly Actuals
B1: FY2025/26 QUARTERLY ACTUALS
B2: GBP millions, unaudited. Green cells are reported actuals from NYSE filings. Q4 (yellow) is the only estimate.
B4: Segment | C4: Q1 (Sep 25) | D4: Q2 (Dec 25) | E4: Q3 (Mar 26) | F4: Q4E (Jun 26) | G4: 9M Actual | H4: FY26E
B5: Commercial | C5: 84.2 | D5: 78.5 | E5: 82.4 | F5: 85 | G5: =SUM(C5:E5) -> 245.1 | H5: =G5+F5 -> 330.1
B6: Broadcasting | C6: 29.9 | D6: 62.3 | E6: 64.9 | F6: 30 | G6: =SUM(C6:E6) -> 157.1 | H6: =G6+F6 -> 187.1
B7: Matchday | C7: 26.2 | D7: 49.5 | E7: 42.2 | F7: 25 | G7: =SUM(C7:E7) -> 117.9 | H7: =G7+F7 -> 142.9
B8: Total revenue | C8: =SUM(C5:C7) -> 140.3 | D8: =SUM(D5:D7) -> 190.3 | E8: =SUM(E5:E7) -> 189.5 | F8: =SUM(F5:F7) -> 140 | G8: =SUM(G5:G7) -> 520.1 | H8: =SUM(H5:H7) -> 660.1
B10: 9-month reported total: £520.1m. FY26 guidance £655-665m (raised 27 May 2026). Q4 to hit the £660m midpoint is ~£140m.

Sheet Assumptions
B1: ASSUMPTIONS
B2: Every input that drives the model. Blue = hardcoded input. Green = calculated elsewhere. Change a blue cell and the whole model recalculates.
B4: REVENUE
B5: Input | C5: Value | D5: Unit
B6: Base revenue (FY26) | C6: 660 | D6: £m
B7: Commercial share | C7: 0.51 | D7: %
B8: Broadcasting share | C8: 0.26 | D8: %
B9: Matchday share | C9: 0.23 | D9: %
B10: Commercial growth | C10: 0.06 | D10: %
B11: Broadcast base growth | C11: 0.02 | D11: %
B12: Matchday growth | C12: 0.02 | D12: %
B14: CHAMPIONS LEAGUE (probability-weighted)
B15: Input | C15: Value | D15: Unit
B16: UCL broadcast uplift | C16: 60 | D16: £m
B17: UCL prob Year 1 (FY27) | C17: 1 | D17: %
B18: UCL prob Year 2 (FY28) | C18: 0.65 | D18: %
B19: UCL prob Year 3 (FY29) | C19: 0.6 | D19: %
B20: UCL prob Year 4 (FY30) | C20: 0.57 | D20: %
B21: UCL prob Year 5 (FY31) | C21: 0.55 | D21: %
B23: COSTS
B24: Input | C24: Value | D24: Unit
B25: Wages % revenue (base) | C25: 0.52 | D25: %
B26: Wage stickiness factor | C26: 0.03 | D26: %
B27: Other opex % revenue | C27: 0.18 | D27: %
B28: Player amortisation | C28: 210 | D28: £m
B29: Net transfer capex | C29: 120 | D29: £m
B30: NWC change % revenue | C30: 0.01 | D30: %
B31: Tax rate | C31: 0.25 | D31: %
B33: VALUATION
B34: Input | C34: Value | D34: Unit
B35: WACC | C35: 0.0963 | D35: %
B36: Terminal growth rate | C36: 0.02 | D36: %
B37: Net debt | C37: 691.7 | D37: £m
B38: Shares outstanding | C38: 172 | D38: m
B39: Share price (USD) | C39: 22.23 | D39: $
B40: USD to GBP | C40: 0.745 | D40: x

Sheet WACC Build
B1: WACC BUILD
B2: Cost of equity via CAPM with beta regressed from 105 weekly returns (Jul 2024-Jul 2026). Blue = input. Black = formula.
B4: SECTION 1 — COST OF EQUITY (CAPM)
B5: Component | C5: Value
B6: Risk-free rate (US 10Y Treasury) | C6: 0.0435
B7: Raw beta (2Y weekly regression) | C7: 0.6497
B8: Vasicek-adjusted beta | C8: =(2/3)*C7+(1/3)*1 -> 0.76646667
B9: Equity risk premium (ERP) | C9: 0.052
B10: Size premium (micro-cap) | C10: 0.015
B11: Company-specific premium | C11: 0.01
B12: = COST OF EQUITY | C12: =C6+C8*C9+C10+C11 -> 0.10835627
B14: SECTION 2 — COST OF DEBT
B15: Component | C15: Value
B16: Pre-tax cost of debt | C16: 0.0625
B17: Tax rate | C17: 0.25
B18: = AFTER-TAX COST OF DEBT | C18: =C16*(1-C17) -> 0.046875
B20: SECTION 3 — CAPITAL STRUCTURE & WACC
B21: Component | C21: Value
B22: Market cap (£m) | C22: =Assumptions!$C$38*Assumptions!$C$39*Assumptions!$C$40 -> 2848.5522
B23: Net debt (£m) | C23: =Assumptions!$C$37 -> 691.7
B24: Total capital (£m) | C24: =C22+C23 -> 3540.2522
B25: Weight of equity | C25: =C22/C24 -> 0.80461844
B26: Weight of debt | C26: =C23/C24 -> 0.19538156
B27: = WACC | C27: =C25*C12+C26*C18 -> 0.096343961

Sheet Revenue Build
B1: REVENUE BUILD
B2: GBP millions. FY25/26 is the reported base year; FY26/27 onward projected. Broadcasting includes the probability-weighted Champions League uplift.
B4: Segment | C4: FY25/26 | D4: FY26/27E | E4: FY27/28E | F4: FY28/29E | G4: FY29/30E | H4: FY30/31E
B5: UCL qualification probability | C5: 0 | D5: =Assumptions!$C$17 -> 1 | E5: =Assumptions!$C$18 -> 0.65 | F5: =Assumptions!$C$19 -> 0.6 | G5: =Assumptions!$C$20 -> 0.57 | H5: =Assumptions!$C$21 -> 0.55
B6: Commercial | C6: =Assumptions!$C$6*Assumptions!$C$7 -> 336.6 | D6: =Assumptions!$C$6*Assumptions!$C$7*(1+Assumptions!$C$10)^1 -> 356.796 | E6: =Assumptions!$C$6*Assumptions!$C$7*(1+Assumptions!$C$10)^2 -> 378.20376 | F6: =Assumptions!$C$6*Assumptions!$C$7*(1+Assumptions!$C$10)^3 -> 400.89599 | G6: =Assumptions!$C$6*Assumptions!$C$7*(1+Assumptions!$C$10)^4 -> 424.94974 | H6: =Assumptions!$C$6*Assumptions!$C$7*(1+Assumptions!$C$10)^5 -> 450.44673
B7: Broadcasting (incl. UCL) | C7: =Assumptions!$C$6*Assumptions!$C$8 -> 171.6 | D7: =Assumptions!$C$6*Assumptions!$C$8*(1+Assumptions!$C$11)^1+Assumptions!$C$16*D5 -> 235.032 | E7: =Assumptions!$C$6*Assumptions!$C$8*(1+Assumptions!$C$11)^2+Assumptions!$C$16*E5 -> 217.53264 | F7: =Assumptions!$C$6*Assumptions!$C$8*(1+Assumptions!$C$11)^3+Assumptions!$C$16*F5 -> 218.10329 | G7: =Assumptions!$C$6*Assumptions!$C$8*(1+Assumptions!$C$11)^4+Assumptions!$C$16*G5 -> 219.94536 | H7: =Assumptions!$C$6*Assumptions!$C$8*(1+Assumptions!$C$11)^5+Assumptions!$C$16*H5 -> 222.46027
B8: Matchday | C8: =Assumptions!$C$6*Assumptions!$C$9 -> 151.8 | D8: =Assumptions!$C$6*Assumptions!$C$9*(1+Assumptions!$C$12)^1 -> 154.836 | E8: =Assumptions!$C$6*Assumptions!$C$9*(1+Assumptions!$C$12)^2 -> 157.93272 | F8: =Assumptions!$C$6*Assumptions!$C$9*(1+Assumptions!$C$12)^3 -> 161.09137 | G8: =Assumptions!$C$6*Assumptions!$C$9*(1+Assumptions!$C$12)^4 -> 164.3132 | H8: =Assumptions!$C$6*Assumptions!$C$9*(1+Assumptions!$C$12)^5 -> 167.59947
B9: TOTAL REVENUE | C9: =SUM(C6:C8) -> 660 | D9: =SUM(D6:D8) -> 746.664 | E9: =SUM(E6:E8) -> 753.66912 | F9: =SUM(F6:F8) -> 780.09065 | G9: =SUM(G6:G8) -> 809.20831 | H9: =SUM(H6:H8) -> 840.50646
B10: Revenue growth YoY | D10: =D9/C9-1 -> 0.13130909 | E10: =E9/D9-1 -> 0.0093818907 | F10: =F9/E9-1 -> 0.035057205 | G10: =G9/F9-1 -> 0.037325986 | H10: =H9/G9-1 -> 0.038677502
B12: FY25/26 is the base year: United finished 3rd but was NOT in the Champions League that season, so its broadcasting excludes the UCL uplift. From FY26/27 the uplift is added, weighted by qualification probability which is 100% year one (confirmed), then declining.

Sheet P&L to FCF
B1: P&L TO FREE CASH FLOW
B2: Base case with wage-stickiness feedback: wages % rises as UCL probability falls. All £m.
B4: Line | C4: FY26/27E | D4: FY27/28E | E4: FY28/29E | F4: FY29/30E | G4: FY30/31E
B5: Revenue | C5: ='Revenue Build'!D9 -> 746.664 | D5: ='Revenue Build'!E9 -> 753.66912 | E5: ='Revenue Build'!F9 -> 780.09065 | F5: ='Revenue Build'!G9 -> 809.20831 | G5: ='Revenue Build'!H9 -> 840.50646
B6: Wage % (feedback-adjusted) | C6: =Assumptions!$C$25+Assumptions!$C$26*(1-'Revenue Build'!D5) -> 0.52 | D6: =Assumptions!$C$25+Assumptions!$C$26*(1-'Revenue Build'!E5) -> 0.5305 | E6: =Assumptions!$C$25+Assumptions!$C$26*(1-'Revenue Build'!F5) -> 0.532 | F6: =Assumptions!$C$25+Assumptions!$C$26*(1-'Revenue Build'!G5) -> 0.5329 | G6: =Assumptions!$C$25+Assumptions!$C$26*(1-'Revenue Build'!H5) -> 0.5335
B7: Less: Wages | C7: =-C5*C6 -> -388.26528 | D7: =-D5*D6 -> -399.82147 | E7: =-E5*E6 -> -415.00823 | F7: =-F5*F6 -> -431.22711 | G7: =-G5*G6 -> -448.4102
B8: Less: Other opex | C8: =-C5*Assumptions!$C$27 -> -134.39952 | D8: =-D5*Assumptions!$C$27 -> -135.66044 | E8: =-E5*Assumptions!$C$27 -> -140.41632 | F8: =-F5*Assumptions!$C$27 -> -145.6575 | G8: =-G5*Assumptions!$C$27 -> -151.29116
B9: EBITDA | C9: =C5+C7+C8 -> 223.9992 | D9: =D5+D7+D8 -> 218.18721 | E9: =E5+E7+E8 -> 224.66611 | F9: =F5+F7+F8 -> 232.3237 | G9: =G5+G7+G8 -> 240.8051
B10: Less: Player amortisation | C10: =-Assumptions!$C$28 -> -210 | D10: =-Assumptions!$C$28 -> -210 | E10: =-Assumptions!$C$28 -> -210 | F10: =-Assumptions!$C$28 -> -210 | G10: =-Assumptions!$C$28 -> -210
B11: EBIT | C11: =C9+C10 -> 13.9992 | D11: =D9+D10 -> 8.1872102 | E11: =E9+E10 -> 14.666108 | F11: =F9+F10 -> 22.323704 | G11: =G9+G10 -> 30.805101
B12: Less: Tax | C12: =-MAX(0,C11*Assumptions!$C$31) -> -3.4998 | D12: =-MAX(0,D11*Assumptions!$C$31) -> -2.0468026 | E12: =-MAX(0,E11*Assumptions!$C$31) -> -3.666527 | F12: =-MAX(0,F11*Assumptions!$C$31) -> -5.5809261 | G12: =-MAX(0,G11*Assumptions!$C$31) -> -7.7012753
B13: Add: Amortisation (non-cash) | C13: =Assumptions!$C$28 -> 210 | D13: =Assumptions!$C$28 -> 210 | E13: =Assumptions!$C$28 -> 210 | F13: =Assumptions!$C$28 -> 210 | G13: =Assumptions!$C$28 -> 210
B14: Less: Transfer capex | C14: =-Assumptions!$C$29 -> -120 | D14: =-Assumptions!$C$29 -> -120 | E14: =-Assumptions!$C$29 -> -120 | F14: =-Assumptions!$C$29 -> -120 | G14: =-Assumptions!$C$29 -> -120
B15: Less: NWC change | C15: =-C5*Assumptions!$C$30 -> -7.46664 | D15: =-D5*Assumptions!$C$30 -> -7.5366912 | E15: =-E5*Assumptions!$C$30 -> -7.8009065 | F15: =-F5*Assumptions!$C$30 -> -8.0920831 | G15: =-G5*Assumptions!$C$30 -> -8.4050646
B16: FREE CASH FLOW | C16: =C11+C12+C13+C14+C15 -> 93.03276 | D16: =D11+D12+D13+D14+D15 -> 88.603716 | E16: =E11+E12+E13+E14+E15 -> 93.198674 | F16: =F11+F12+F13+F14+F15 -> 98.650695 | G16: =G11+G12+G13+G14+G15 -> 104.69876

Sheet DCF
B1: DCF VALUATION
B2: Base case DCF with terminal value and equity bridge. Green = links.
B4: Line | C4: FY26/27E | D4: FY27/28E | E4: FY28/29E | F4: FY29/30E | G4: FY30/31E
B5: Free cash flow | C5: ='P&L to FCF'!C16 -> 93.03276 | D5: ='P&L to FCF'!D16 -> 88.603716 | E5: ='P&L to FCF'!E16 -> 93.198674 | F5: ='P&L to FCF'!F16 -> 98.650695 | G5: ='P&L to FCF'!G16 -> 104.69876
B6: Discount factor | C6: =1/(1+Assumptions!$C$35)^1 -> 0.91215908 | D6: =1/(1+Assumptions!$C$35)^2 -> 0.83203419 | E6: =1/(1+Assumptions!$C$35)^3 -> 0.75894754 | F6: =1/(1+Assumptions!$C$35)^4 -> 0.69228089 | G6: =1/(1+Assumptions!$C$35)^5 -> 0.6314703
B7: PV of FCF | C7: =C5*C6 -> 84.860677 | D7: =D5*D6 -> 73.721321 | E7: =E5*E6 -> 70.732905 | F7: =F5*F6 -> 68.293991 | G7: =G5*G6 -> 66.114158
B9: VALUATION
B10: Sum of PV of FCFs (£m) | C10: =SUM(C7:G7) -> 363.72305
B11: Terminal value (£m) | C11: =G5*(1+Assumptions!$C$36)/(Assumptions!$C$35-Assumptions!$C$36) -> 1399.6427
B12: PV of terminal value (£m) | C12: =C11/(1+Assumptions!$C$35)^5 -> 883.83278
B13: ENTERPRISE VALUE (£m) | C13: =C10+C12 -> 1247.5558
B14: Less: Net debt (£m) | C14: =-Assumptions!$C$37 -> -691.7
B15: EQUITY VALUE (£m) | C15: =C13+C14 -> 555.85584
B16: Equity value (USD m) | C16: =C15/Assumptions!$C$40 -> 746.11522
B17: VALUE PER SHARE (USD) | C17: =C16/Assumptions!$C$38 -> 4.3378792
B18: Current market price (USD) | C18: =Assumptions!$C$39 -> 22.23
B19: Upside / (downside) | C19: =C17/C18-1 -> -0.80486374
B21: SCENARIOS
B22: Driver | C22: Bear | D22: Base | E22: Bull
B23: Wages as % of revenue | C23: 0.58 | D23: =Assumptions!$C$25 -> 0.52 | E23: 0.5
B24: Commercial growth haircut | C24: 0.05 | D24: 0 | E24: 0
B25: UCL qualification by year | C25: Yr 1 only | D25: Probability-weighted | E25: Every year
B27: SCENARIO CALCULATIONS
B28: Line | C28: Yr1 | D28: Yr2 | E28: Yr3 | F28: Yr4 | G28: Yr5 | H28: Result
B29: Bear - UCL indicator | C29: 1 | D29: 0 | E29: 0 | F29: 0 | G29: 0
B30: Bear - revenue | C30: =Assumptions!$C$6*Assumptions!$C$7*(1+Assumptions!$C$10-$C$24*(1-C$29))^1+Assumptions!$C$6*Assumptions!$C$8*(1+Assumptions!$C$11)^1+Assumptions!$C$16*C$29+Assumptions!$C$6*Assumptions!$C$9*(1+Assumptions!$C$12)^1 -> 746.664 | D30: =Assumptions!$C$6*Assumptions!$C$7*(1+Assumptions!$C$10-$C$24*(1-D$29))^2+Assumptions!$C$6*Assumptions!$C$8*(1+Assumptions!$C$11)^2+Assumptions!$C$16*D$29+Assumptions!$C$6*Assumptions!$C$9*(1+Assumptions!$C$12)^2 -> 679.83102 | E30: =Assumptions!$C$6*Assumptions!$C$7*(1+Assumptions!$C$10-$C$24*(1-E$29))^3+Assumptions!$C$6*Assumptions!$C$8*(1+Assumptions!$C$11)^3+Assumptions!$C$16*E$29+Assumptions!$C$6*Assumptions!$C$9*(1+Assumptions!$C$12)^3 -> 689.99398 | F30: =Assumptions!$C$6*Assumptions!$C$7*(1+Assumptions!$C$10-$C$24*(1-F$29))^4+Assumptions!$C$6*Assumptions!$C$8*(1+Assumptions!$C$11)^4+Assumptions!$C$16*F$29+Assumptions!$C$6*Assumptions!$C$9*(1+Assumptions!$C$12)^4 -> 700.32587 | G30: =Assumptions!$C$6*Assumptions!$C$7*(1+Assumptions!$C$10-$C$24*(1-G$29))^5+Assumptions!$C$6*Assumptions!$C$8*(1+Assumptions!$C$11)^5+Assumptions!$C$16*G$29+Assumptions!$C$6*Assumptions!$C$9*(1+Assumptions!$C$12)^5 -> 710.82971
B31: Bear - free cash flow | C31: =(C$30*(1-$C$23-Assumptions!$C$27)-Assumptions!$C$28)-MAX(0,(C$30*(1-$C$23-Assumptions!$C$27)-Assumptions!$C$28)*Assumptions!$C$31)+Assumptions!$C$28-Assumptions!$C$29-C$30*Assumptions!$C$30 -> 51.73272 | D31: =(D$30*(1-$C$23-Assumptions!$C$27)-Assumptions!$C$28)-MAX(0,(D$30*(1-$C$23-Assumptions!$C$27)-Assumptions!$C$28)*Assumptions!$C$31)+Assumptions!$C$28-Assumptions!$C$29-D$30*Assumptions!$C$30 -> 36.361135 | E31: =(E$30*(1-$C$23-Assumptions!$C$27)-Assumptions!$C$28)-MAX(0,(E$30*(1-$C$23-Assumptions!$C$27)-Assumptions!$C$28)*Assumptions!$C$31)+Assumptions!$C$28-Assumptions!$C$29-E$30*Assumptions!$C$30 -> 38.698616 | F31: =(F$30*(1-$C$23-Assumptions!$C$27)-Assumptions!$C$28)-MAX(0,(F$30*(1-$C$23-Assumptions!$C$27)-Assumptions!$C$28)*Assumptions!$C$31)+Assumptions!$C$28-Assumptions!$C$29-F$30*Assumptions!$C$30 -> 41.07495 | G31: =(G$30*(1-$C$23-Assumptions!$C$27)-Assumptions!$C$28)-MAX(0,(G$30*(1-$C$23-Assumptions!$C$27)-Assumptions!$C$28)*Assumptions!$C$31)+Assumptions!$C$28-Assumptions!$C$29-G$30*Assumptions!$C$30 -> 43.490834 | H31: =((C$31/(1+Assumptions!$C$35)^1+D$31/(1+Assumptions!$C$35)^2+E$31/(1+Assumptions!$C$35)^3+F$31/(1+Assumptions!$C$35)^4+G$31/(1+Assumptions!$C$35)^5+G$31*(1+Assumptions!$C$36)/(Assumptions!$C$35-Assumptions!$C$36)/(1+Assumptions!$C$35)^5)-Assumptions!$C$37)/Assumptions!$C$40/Assumptions!$C$38 -> -1.2630997
B32: Bull - UCL indicator | C32: 1 | D32: 1 | E32: 1 | F32: 1 | G32: 1
B33: Bull - revenue | C33: =Assumptions!$C$6*Assumptions!$C$7*(1+Assumptions!$C$10-$E$24*(1-C$32))^1+Assumptions!$C$6*Assumptions!$C$8*(1+Assumptions!$C$11)^1+Assumptions!$C$16*C$32+Assumptions!$C$6*Assumptions!$C$9*(1+Assumptions!$C$12)^1 -> 746.664 | D33: =Assumptions!$C$6*Assumptions!$C$7*(1+Assumptions!$C$10-$E$24*(1-D$32))^2+Assumptions!$C$6*Assumptions!$C$8*(1+Assumptions!$C$11)^2+Assumptions!$C$16*D$32+Assumptions!$C$6*Assumptions!$C$9*(1+Assumptions!$C$12)^2 -> 774.66912 | E33: =Assumptions!$C$6*Assumptions!$C$7*(1+Assumptions!$C$10-$E$24*(1-E$32))^3+Assumptions!$C$6*Assumptions!$C$8*(1+Assumptions!$C$11)^3+Assumptions!$C$16*E$32+Assumptions!$C$6*Assumptions!$C$9*(1+Assumptions!$C$12)^3 -> 804.09065 | F33: =Assumptions!$C$6*Assumptions!$C$7*(1+Assumptions!$C$10-$E$24*(1-F$32))^4+Assumptions!$C$6*Assumptions!$C$8*(1+Assumptions!$C$11)^4+Assumptions!$C$16*F$32+Assumptions!$C$6*Assumptions!$C$9*(1+Assumptions!$C$12)^4 -> 835.00831 | G33: =Assumptions!$C$6*Assumptions!$C$7*(1+Assumptions!$C$10-$E$24*(1-G$32))^5+Assumptions!$C$6*Assumptions!$C$8*(1+Assumptions!$C$11)^5+Assumptions!$C$16*G$32+Assumptions!$C$6*Assumptions!$C$9*(1+Assumptions!$C$12)^5 -> 867.50646
B34: Bull - free cash flow | C34: =(C$33*(1-$E$23-Assumptions!$C$27)-Assumptions!$C$28)-MAX(0,(C$33*(1-$E$23-Assumptions!$C$27)-Assumptions!$C$28)*Assumptions!$C$31)+Assumptions!$C$28-Assumptions!$C$29-C$33*Assumptions!$C$30 -> 104.23272 | D34: =(D$33*(1-$E$23-Assumptions!$C$27)-Assumptions!$C$28)-MAX(0,(D$33*(1-$E$23-Assumptions!$C$27)-Assumptions!$C$28)*Assumptions!$C$31)+Assumptions!$C$28-Assumptions!$C$29-D$33*Assumptions!$C$30 -> 110.6739 | E34: =(E$33*(1-$E$23-Assumptions!$C$27)-Assumptions!$C$28)-MAX(0,(E$33*(1-$E$23-Assumptions!$C$27)-Assumptions!$C$28)*Assumptions!$C$31)+Assumptions!$C$28-Assumptions!$C$29-E$33*Assumptions!$C$30 -> 117.44085 | F34: =(F$33*(1-$E$23-Assumptions!$C$27)-Assumptions!$C$28)-MAX(0,(F$33*(1-$E$23-Assumptions!$C$27)-Assumptions!$C$28)*Assumptions!$C$31)+Assumptions!$C$28-Assumptions!$C$29-F$33*Assumptions!$C$30 -> 124.55191 | G34: =(G$33*(1-$E$23-Assumptions!$C$27)-Assumptions!$C$28)-MAX(0,(G$33*(1-$E$23-Assumptions!$C$27)-Assumptions!$C$28)*Assumptions!$C$31)+Assumptions!$C$28-Assumptions!$C$29-G$33*Assumptions!$C$30 -> 132.02649 | H34: =((C$34/(1+Assumptions!$C$35)^1+D$34/(1+Assumptions!$C$35)^2+E$34/(1+Assumptions!$C$35)^3+F$34/(1+Assumptions!$C$35)^4+G$34/(1+Assumptions!$C$35)^5+G$34*(1+Assumptions!$C$36)/(Assumptions!$C$35-Assumptions!$C$36)/(1+Assumptions!$C$35)^5)-Assumptions!$C$37)/Assumptions!$C$40/Assumptions!$C$38 -> 6.7794051
B36: EQUITY VALUE PER SHARE | C36: =H31 -> -1.2630997 | D36: =C17 -> 4.3378792 | E36: =H34 -> 6.7794051
B37: vs market price | C37: =C36/Assumptions!$C$39-1 -> -1.0568196 | D37: =D36/Assumptions!$C$39-1 -> -0.80486374 | E37: =E36/Assumptions!$C$39-1 -> -0.69503351

Sheet Validation
B1: VALIDATION : MODEL vs MARKET
B2: Cross-check of DCF intrinsic value against the live NYSE price and what the model omits.
B4: MODEL vs MARKET
B5: Metric | C5: Value | D5: Note
B6: DCF intrinsic value / share | C6: =DCF!C17 -> 4.3378792 | D6: Base case, probability-weighted UCL
B7: Current NYSE price | C7: =Assumptions!C39 -> 22.23 | D7: 17 Jul 2026 close
B8: Upside / (downside) | C8: =DCF!C17/Assumptions!C39-1 -> -0.80486374 | D8: Model vs market
B9: 52-week range | C9: $14.59 - $24.22 | D9: Current price near top of range
B10: EPS (TTM) | C10: -$0.14 | D10: Loss-making; no meaningful P/E
B11: Sell-side 1Y target | C11: $23.74 | D11: Consensus above current price
B13: WHAT THIS MODEL DOES NOT CAPTURE
B14: 1. New 100,000-seat stadium: Q3 filing confirms it is in development. Would lift matchday capacity ~35% (£50m+ annual revenue at current per-seat economics). Not in base FCF.
B15: 2. Player asset value : Q3 balance sheet shows £520.8m unamortised registrations. A DCF on operating cash flow does not value the squad as a tradable asset base.
B16: 3. Takeover / control premium : strategic buyers pay above intrinsic value for trophy assets. Glazer ownership keeps bid speculation alive.
B17: 4. Brand optionality : 1.1bn global fans (2019 survey). Commercial monetisation runway beyond the explicit 5-year window.
B18: 5. FX translation risk: evenue largely GBP, listed in USD. Q3 showed a £10.3m unrealised FX loss on USD borrowings in a single quarter.

Sheet Trading Comps
B1: TRADING COMPARABLES : PREMIER LEAGUE
B2: United market cap is LIVE (NYSE public float). Peers are ESTIMATED private valuations that are not directly comparable at the market-cap level. Compare at EV/Revenue instead. All £m.
B4: Club | C4: Mkt Cap | D4: Net Debt | E4: EV | F4: Revenue | G4: EBITDA | H4: EV/Rev | I4: EV/EBITDA | J4: UCL 26/27 | K4: Ownership
B5: Manchester United | C5: =Assumptions!C38*Assumptions!C39*Assumptions!C40 -> 2848.5522 | D5: =Assumptions!C37 -> 691.7 | E5: =C5+D5 -> 3540.2522 | F5: =Assumptions!C6 -> 660 | G5: 210 | H5: =E5/F5 -> 5.3640185 | I5: =E5/G5 -> 16.858344 | J5: Yes | K5: Public (NYSE)
B6: Arsenal | C6: 2400 | D6: -150 | E6: =C6+D6 -> 2250 | F6: 710 | G6: 230 | H6: =E6/F6 -> 3.1690141 | I6: =E6/G6 -> 9.7826087 | J6: Yes | K6: Private (KSE)
B7: Liverpool | C7: 3800 | D7: -80 | E7: =C7+D7 -> 3720 | F7: 700 | G7: 240 | H7: =E7/F7 -> 5.3142857 | I7: =E7/G7 -> 15.5 | J7: Yes | K7: Private (FSG)
B8: Chelsea | C8: 1800 | D8: 1200 | E8: =C8+D8 -> 3000 | F8: 590 | G8: 110 | H8: =E8/F8 -> 5.0847458 | I8: =E8/G8 -> 27.272727 | J8: No | K8: Private (Clearlake)
B9: Tottenham | C9: 420 | D9: 850 | E9: =C9+D9 -> 1270 | F9: 580 | G9: 130 | H9: =E9/F9 -> 2.1896552 | I9: =E9/G9 -> 9.7692308 | J9: No | K9: Private (ENIC)
B10: Median (ex-United) | H10: =MEDIAN(H6:H9) -> 4.1268799 | I10: =MEDIAN(I6:I9) -> 12.641304

Sheet Operating Comps
B1: OPERATING COMPARABLES
B2: How United's business model compares operationally to peers. All £m unless %.
B4: REVENUE MIX (% of total)
B5: Club | C5: Total Rev | D5: Commercial % | E5: Broadcast % | F5: Matchday % | G5: Comm £m | H5: Broad £m | I5: Match £m
B6: Manchester United | C6: 660 | D6: 0.51 | E6: 0.26 | F6: 0.23 | G6: =C6*D6 -> 336.6 | H6: =C6*E6 -> 171.6 | I6: =C6*F6 -> 151.8
B7: Arsenal | C7: 710 | D7: 0.46 | E7: 0.34 | F7: 0.2 | G7: =C7*D7 -> 326.6 | H7: =C7*E7 -> 241.4 | I7: =C7*F7 -> 142
B8: Liverpool | C8: 700 | D8: 0.48 | E8: 0.33 | F8: 0.19 | G8: =C8*D8 -> 336 | H8: =C8*E8 -> 231 | I8: =C8*F8 -> 133
B9: Chelsea | C9: 590 | D9: 0.4 | E9: 0.38 | F9: 0.22 | G9: =C9*D9 -> 236 | H9: =C9*E9 -> 224.2 | I9: =C9*F9 -> 129.8
B10: Tottenham | C10: 580 | D10: 0.43 | E10: 0.36 | F10: 0.21 | G10: =C10*D10 -> 249.4 | H10: =C10*E10 -> 208.8 | I10: =C10*F10 -> 121.8
B12: COST STRUCTURE
B13: Club | C13: Revenue | D13: Wages % | E13: Wages £m | F13: Amort £m | G13: EBITDA margin | H13: EBIT margin | I13: Net transfers
B14: Manchester United | C14: 660 | D14: 0.52 | E14: =C14*D14 -> 343.2 | F14: 210 | G14: 0.3 | H14: 0.02 | I14: 120
B15: Arsenal | C15: 710 | D15: 0.57 | E15: =C15*D15 -> 404.7 | F15: 148 | G15: 0.32 | H15: 0.09 | I15: 85
B16: Liverpool | C16: 700 | D16: 0.55 | E16: =C16*D16 -> 385 | F16: 148 | G16: 0.34 | H16: 0.1 | I16: 75
B17: Chelsea | C17: 590 | D17: 0.68 | E17: =C17*D17 -> 401.2 | F17: 195 | G17: 0.19 | H17: -0.06 | I17: 260
B18: Tottenham | C18: 580 | D18: 0.59 | E18: =C18*D18 -> 342.2 | F18: 140 | G18: 0.22 | H18: 0.02 | I18: 55
B20: KEY TAKEAWAYS
B21: 1. United's commercial share (51%) is the highest in the group the most stable, least UCL-dependent revenue stream. A genuine structural strength.
B22: 2. United's wage ratio (52%) is now the BEST in the peer set post-Ratcliffe down from ~76% in the Glazer era. Chelsea (68%) is the outlier on the wrong side.
B23: 3. United's broadcast share (26%) is lowest a direct scar from the 2024/25 UCL absence. Normalises toward 33%+ with requalification.
B24: 4. Chelsea: 68% wages + £260m net transfers + no European football = visible PSR risk. This is the amortisation-driven squad-cost story in real time.

Sheet Sensitivity
B1: SENSITIVITY : VALUE PER SHARE (USD)
B2: Every cell is a live DCF rerun using the free cash flows from the P&L tab. Change any operating assumption and this whole grid moves. Base case shaded.
B4: WACC \ TGR | C4: 0.01 | D4: 0.015 | E4: 0.02 | F4: 0.025 | G4: 0.03
B5: 0.0863 | C5: =(('P&L to FCF'!$C$16/(1+$B5)^1+'P&L to FCF'!$D$16/(1+$B5)^2+'P&L to FCF'!$E$16/(1+$B5)^3+'P&L to FCF'!$F$16/(1+$B5)^4+'P&L to FCF'!$G$16/(1+$B5)^5+'P&L to FCF'!$G$16*(1+C$4)/($B5-C$4)/(1+$B5)^5)-Assumptions!$C$37)/Assumptions!$C$40/Assumptions!$C$38 -> 4.666668 | D5: =(('P&L to FCF'!$C$16/(1+$B5)^1+'P&L to FCF'!$D$16/(1+$B5)^2+'P&L to FCF'!$E$16/(1+$B5)^3+'P&L to FCF'!$F$16/(1+$B5)^4+'P&L to FCF'!$G$16/(1+$B5)^5+'P&L to FCF'!$G$16*(1+D$4)/($B5-D$4)/(1+$B5)^5)-Assumptions!$C$37)/Assumptions!$C$40/Assumptions!$C$38 -> 5.2059472 | E5: =(('P&L to FCF'!$C$16/(1+$B5)^1+'P&L to FCF'!$D$16/(1+$B5)^2+'P&L to FCF'!$E$16/(1+$B5)^3+'P&L to FCF'!$F$16/(1+$B5)^4+'P&L to FCF'!$G$16/(1+$B5)^5+'P&L to FCF'!$G$16*(1+E$4)/($B5-E$4)/(1+$B5)^5)-Assumptions!$C$37)/Assumptions!$C$40/Assumptions!$C$38 -> 5.8265656 | F5: =(('P&L to FCF'!$C$16/(1+$B5)^1+'P&L to FCF'!$D$16/(1+$B5)^2+'P&L to FCF'!$E$16/(1+$B5)^3+'P&L to FCF'!$F$16/(1+$B5)^4+'P&L to FCF'!$G$16/(1+$B5)^5+'P&L to FCF'!$G$16*(1+F$4)/($B5-F$4)/(1+$B5)^5)-Assumptions!$C$37)/Assumptions!$C$40/Assumptions!$C$38 -> 6.5484268 | G5: =(('P&L to FCF'!$C$16/(1+$B5)^1+'P&L to FCF'!$D$16/(1+$B5)^2+'P&L to FCF'!$E$16/(1+$B5)^3+'P&L to FCF'!$F$16/(1+$B5)^4+'P&L to FCF'!$G$16/(1+$B5)^5+'P&L to FCF'!$G$16*(1+G$4)/($B5-G$4)/(1+$B5)^5)-Assumptions!$C$37)/Assumptions!$C$40/Assumptions!$C$38 -> 7.3985049
B6: 0.0913 | C6: =(('P&L to FCF'!$C$16/(1+$B6)^1+'P&L to FCF'!$D$16/(1+$B6)^2+'P&L to FCF'!$E$16/(1+$B6)^3+'P&L to FCF'!$F$16/(1+$B6)^4+'P&L to FCF'!$G$16/(1+$B6)^5+'P&L to FCF'!$G$16*(1+C$4)/($B6-C$4)/(1+$B6)^5)-Assumptions!$C$37)/Assumptions!$C$40/Assumptions!$C$38 -> 4.0361146 | D6: =(('P&L to FCF'!$C$16/(1+$B6)^1+'P&L to FCF'!$D$16/(1+$B6)^2+'P&L to FCF'!$E$16/(1+$B6)^3+'P&L to FCF'!$F$16/(1+$B6)^4+'P&L to FCF'!$G$16/(1+$B6)^5+'P&L to FCF'!$G$16*(1+D$4)/($B6-D$4)/(1+$B6)^5)-Assumptions!$C$37)/Assumptions!$C$40/Assumptions!$C$38 -> 4.5004536 | E6: =(('P&L to FCF'!$C$16/(1+$B6)^1+'P&L to FCF'!$D$16/(1+$B6)^2+'P&L to FCF'!$E$16/(1+$B6)^3+'P&L to FCF'!$F$16/(1+$B6)^4+'P&L to FCF'!$G$16/(1+$B6)^5+'P&L to FCF'!$G$16*(1+E$4)/($B6-E$4)/(1+$B6)^5)-Assumptions!$C$37)/Assumptions!$C$40/Assumptions!$C$38 -> 5.0299172 | F6: =(('P&L to FCF'!$C$16/(1+$B6)^1+'P&L to FCF'!$D$16/(1+$B6)^2+'P&L to FCF'!$E$16/(1+$B6)^3+'P&L to FCF'!$F$16/(1+$B6)^4+'P&L to FCF'!$G$16/(1+$B6)^5+'P&L to FCF'!$G$16*(1+F$4)/($B6-F$4)/(1+$B6)^5)-Assumptions!$C$37)/Assumptions!$C$40/Assumptions!$C$38 -> 5.6392396 | G6: =(('P&L to FCF'!$C$16/(1+$B6)^1+'P&L to FCF'!$D$16/(1+$B6)^2+'P&L to FCF'!$E$16/(1+$B6)^3+'P&L to FCF'!$F$16/(1+$B6)^4+'P&L to FCF'!$G$16/(1+$B6)^5+'P&L to FCF'!$G$16*(1+G$4)/($B6-G$4)/(1+$B6)^5)-Assumptions!$C$37)/Assumptions!$C$40/Assumptions!$C$38 -> 6.3479621
B7: 0.0963 | C7: =(('P&L to FCF'!$C$16/(1+$B7)^1+'P&L to FCF'!$D$16/(1+$B7)^2+'P&L to FCF'!$E$16/(1+$B7)^3+'P&L to FCF'!$F$16/(1+$B7)^4+'P&L to FCF'!$G$16/(1+$B7)^5+'P&L to FCF'!$G$16*(1+C$4)/($B7-C$4)/(1+$B7)^5)-Assumptions!$C$37)/Assumptions!$C$40/Assumptions!$C$38 -> 3.4788581 | D7: =(('P&L to FCF'!$C$16/(1+$B7)^1+'P&L to FCF'!$D$16/(1+$B7)^2+'P&L to FCF'!$E$16/(1+$B7)^3+'P&L to FCF'!$F$16/(1+$B7)^4+'P&L to FCF'!$G$16/(1+$B7)^5+'P&L to FCF'!$G$16*(1+D$4)/($B7-D$4)/(1+$B7)^5)-Assumptions!$C$37)/Assumptions!$C$40/Assumptions!$C$38 -> 3.8819534 | E7: =(('P&L to FCF'!$C$16/(1+$B7)^1+'P&L to FCF'!$D$16/(1+$B7)^2+'P&L to FCF'!$E$16/(1+$B7)^3+'P&L to FCF'!$F$16/(1+$B7)^4+'P&L to FCF'!$G$16/(1+$B7)^5+'P&L to FCF'!$G$16*(1+E$4)/($B7-E$4)/(1+$B7)^5)-Assumptions!$C$37)/Assumptions!$C$40/Assumptions!$C$38 -> 4.3378792 | F7: =(('P&L to FCF'!$C$16/(1+$B7)^1+'P&L to FCF'!$D$16/(1+$B7)^2+'P&L to FCF'!$E$16/(1+$B7)^3+'P&L to FCF'!$F$16/(1+$B7)^4+'P&L to FCF'!$G$16/(1+$B7)^5+'P&L to FCF'!$G$16*(1+F$4)/($B7-F$4)/(1+$B7)^5)-Assumptions!$C$37)/Assumptions!$C$40/Assumptions!$C$38 -> 4.8577496 | G7: =(('P&L to FCF'!$C$16/(1+$B7)^1+'P&L to FCF'!$D$16/(1+$B7)^2+'P&L to FCF'!$E$16/(1+$B7)^3+'P&L to FCF'!$F$16/(1+$B7)^4+'P&L to FCF'!$G$16/(1+$B7)^5+'P&L to FCF'!$G$16*(1+G$4)/($B7-G$4)/(1+$B7)^5)-Assumptions!$C$37)/Assumptions!$C$40/Assumptions!$C$38 -> 5.4560318
B8: 0.1013 | C8: =(('P&L to FCF'!$C$16/(1+$B8)^1+'P&L to FCF'!$D$16/(1+$B8)^2+'P&L to FCF'!$E$16/(1+$B8)^3+'P&L to FCF'!$F$16/(1+$B8)^4+'P&L to FCF'!$G$16/(1+$B8)^5+'P&L to FCF'!$G$16*(1+C$4)/($B8-C$4)/(1+$B8)^5)-Assumptions!$C$37)/Assumptions!$C$40/Assumptions!$C$38 -> 2.9828506 | D8: =(('P&L to FCF'!$C$16/(1+$B8)^1+'P&L to FCF'!$D$16/(1+$B8)^2+'P&L to FCF'!$E$16/(1+$B8)^3+'P&L to FCF'!$F$16/(1+$B8)^4+'P&L to FCF'!$G$16/(1+$B8)^5+'P&L to FCF'!$G$16*(1+D$4)/($B8-D$4)/(1+$B8)^5)-Assumptions!$C$37)/Assumptions!$C$40/Assumptions!$C$38 -> 3.3353211 | E8: =(('P&L to FCF'!$C$16/(1+$B8)^1+'P&L to FCF'!$D$16/(1+$B8)^2+'P&L to FCF'!$E$16/(1+$B8)^3+'P&L to FCF'!$F$16/(1+$B8)^4+'P&L to FCF'!$G$16/(1+$B8)^5+'P&L to FCF'!$G$16*(1+E$4)/($B8-E$4)/(1+$B8)^5)-Assumptions!$C$37)/Assumptions!$C$40/Assumptions!$C$38 -> 3.7311458 | F8: =(('P&L to FCF'!$C$16/(1+$B8)^1+'P&L to FCF'!$D$16/(1+$B8)^2+'P&L to FCF'!$E$16/(1+$B8)^3+'P&L to FCF'!$F$16/(1+$B8)^4+'P&L to FCF'!$G$16/(1+$B8)^5+'P&L to FCF'!$G$16*(1+F$4)/($B8-F$4)/(1+$B8)^5)-Assumptions!$C$37)/Assumptions!$C$40/Assumptions!$C$38 -> 4.1788479 | G8: =(('P&L to FCF'!$C$16/(1+$B8)^1+'P&L to FCF'!$D$16/(1+$B8)^2+'P&L to FCF'!$E$16/(1+$B8)^3+'P&L to FCF'!$F$16/(1+$B8)^4+'P&L to FCF'!$G$16/(1+$B8)^5+'P&L to FCF'!$G$16*(1+G$4)/($B8-G$4)/(1+$B8)^5)-Assumptions!$C$37)/Assumptions!$C$40/Assumptions!$C$38 -> 4.6893414
B9: 0.1063 | C9: =(('P&L to FCF'!$C$16/(1+$B9)^1+'P&L to FCF'!$D$16/(1+$B9)^2+'P&L to FCF'!$E$16/(1+$B9)^3+'P&L to FCF'!$F$16/(1+$B9)^4+'P&L to FCF'!$G$16/(1+$B9)^5+'P&L to FCF'!$G$16*(1+C$4)/($B9-C$4)/(1+$B9)^5)-Assumptions!$C$37)/Assumptions!$C$40/Assumptions!$C$38 -> 2.5385468 | D9: =(('P&L to FCF'!$C$16/(1+$B9)^1+'P&L to FCF'!$D$16/(1+$B9)^2+'P&L to FCF'!$E$16/(1+$B9)^3+'P&L to FCF'!$F$16/(1+$B9)^4+'P&L to FCF'!$G$16/(1+$B9)^5+'P&L to FCF'!$G$16*(1+D$4)/($B9-D$4)/(1+$B9)^5)-Assumptions!$C$37)/Assumptions!$C$40/Assumptions!$C$38 -> 2.8487442 | E9: =(('P&L to FCF'!$C$16/(1+$B9)^1+'P&L to FCF'!$D$16/(1+$B9)^2+'P&L to FCF'!$E$16/(1+$B9)^3+'P&L to FCF'!$F$16/(1+$B9)^4+'P&L to FCF'!$G$16/(1+$B9)^5+'P&L to FCF'!$G$16*(1+E$4)/($B9-E$4)/(1+$B9)^5)-Assumptions!$C$37)/Assumptions!$C$40/Assumptions!$C$38 -> 3.1948857 | F9: =(('P&L to FCF'!$C$16/(1+$B9)^1+'P&L to FCF'!$D$16/(1+$B9)^2+'P&L to FCF'!$E$16/(1+$B9)^3+'P&L to FCF'!$F$16/(1+$B9)^4+'P&L to FCF'!$G$16/(1+$B9)^5+'P&L to FCF'!$G$16*(1+F$4)/($B9-F$4)/(1+$B9)^5)-Assumptions!$C$37)/Assumptions!$C$40/Assumptions!$C$38 -> 3.5836029 | G9: =(('P&L to FCF'!$C$16/(1+$B9)^1+'P&L to FCF'!$D$16/(1+$B9)^2+'P&L to FCF'!$E$16/(1+$B9)^3+'P&L to FCF'!$F$16/(1+$B9)^4+'P&L to FCF'!$G$16/(1+$B9)^5+'P&L to FCF'!$G$16*(1+G$4)/($B9-G$4)/(1+$B9)^5)-Assumptions!$C$37)/Assumptions!$C$40/Assumptions!$C$38 -> 4.0232661
B10: 0.1113 | C10: =(('P&L to FCF'!$C$16/(1+$B10)^1+'P&L to FCF'!$D$16/(1+$B10)^2+'P&L to FCF'!$E$16/(1+$B10)^3+'P&L to FCF'!$F$16/(1+$B10)^4+'P&L to FCF'!$G$16/(1+$B10)^5+'P&L to FCF'!$G$16*(1+C$4)/($B10-C$4)/(1+$B10)^5)-Assumptions!$C$37)/Assumptions!$C$40/Assumptions!$C$38 -> 2.138286 | D10: =(('P&L to FCF'!$C$16/(1+$B10)^1+'P&L to FCF'!$D$16/(1+$B10)^2+'P&L to FCF'!$E$16/(1+$B10)^3+'P&L to FCF'!$F$16/(1+$B10)^4+'P&L to FCF'!$G$16/(1+$B10)^5+'P&L to FCF'!$G$16*(1+D$4)/($B10-D$4)/(1+$B10)^5)-Assumptions!$C$37)/Assumptions!$C$40/Assumptions!$C$38 -> 2.4128641 | E10: =(('P&L to FCF'!$C$16/(1+$B10)^1+'P&L to FCF'!$D$16/(1+$B10)^2+'P&L to FCF'!$E$16/(1+$B10)^3+'P&L to FCF'!$F$16/(1+$B10)^4+'P&L to FCF'!$G$16/(1+$B10)^5+'P&L to FCF'!$G$16*(1+E$4)/($B10-E$4)/(1+$B10)^5)-Assumptions!$C$37)/Assumptions!$C$40/Assumptions!$C$38 -> 2.7175164 | F10: =(('P&L to FCF'!$C$16/(1+$B10)^1+'P&L to FCF'!$D$16/(1+$B10)^2+'P&L to FCF'!$E$16/(1+$B10)^3+'P&L to FCF'!$F$16/(1+$B10)^4+'P&L to FCF'!$G$16/(1+$B10)^5+'P&L to FCF'!$G$16*(1+F$4)/($B10-F$4)/(1+$B10)^5)-Assumptions!$C$37)/Assumptions!$C$40/Assumptions!$C$38 -> 3.0574703 | G10: =(('P&L to FCF'!$C$16/(1+$B10)^1+'P&L to FCF'!$D$16/(1+$B10)^2+'P&L to FCF'!$E$16/(1+$B10)^3+'P&L to FCF'!$F$16/(1+$B10)^4+'P&L to FCF'!$G$16/(1+$B10)^5+'P&L to FCF'!$G$16*(1+G$4)/($B10-G$4)/(1+$B10)^5)-Assumptions!$C$37)/Assumptions!$C$40/Assumptions!$C$38 -> 3.4392389
B11: 0.1163 | C11: =(('P&L to FCF'!$C$16/(1+$B11)^1+'P&L to FCF'!$D$16/(1+$B11)^2+'P&L to FCF'!$E$16/(1+$B11)^3+'P&L to FCF'!$F$16/(1+$B11)^4+'P&L to FCF'!$G$16/(1+$B11)^5+'P&L to FCF'!$G$16*(1+C$4)/($B11-C$4)/(1+$B11)^5)-Assumptions!$C$37)/Assumptions!$C$40/Assumptions!$C$38 -> 1.7758489 | D11: =(('P&L to FCF'!$C$16/(1+$B11)^1+'P&L to FCF'!$D$16/(1+$B11)^2+'P&L to FCF'!$E$16/(1+$B11)^3+'P&L to FCF'!$F$16/(1+$B11)^4+'P&L to FCF'!$G$16/(1+$B11)^5+'P&L to FCF'!$G$16*(1+D$4)/($B11-D$4)/(1+$B11)^5)-Assumptions!$C$37)/Assumptions!$C$40/Assumptions!$C$38 -> 2.0201697 | E11: =(('P&L to FCF'!$C$16/(1+$B11)^1+'P&L to FCF'!$D$16/(1+$B11)^2+'P&L to FCF'!$E$16/(1+$B11)^3+'P&L to FCF'!$F$16/(1+$B11)^4+'P&L to FCF'!$G$16/(1+$B11)^5+'P&L to FCF'!$G$16*(1+E$4)/($B11-E$4)/(1+$B11)^5)-Assumptions!$C$37)/Assumptions!$C$40/Assumptions!$C$38 -> 2.2898613 | F11: =(('P&L to FCF'!$C$16/(1+$B11)^1+'P&L to FCF'!$D$16/(1+$B11)^2+'P&L to FCF'!$E$16/(1+$B11)^3+'P&L to FCF'!$F$16/(1+$B11)^4+'P&L to FCF'!$G$16/(1+$B11)^5+'P&L to FCF'!$G$16*(1+F$4)/($B11-F$4)/(1+$B11)^5)-Assumptions!$C$37)/Assumptions!$C$40/Assumptions!$C$38 -> 2.5890919 | G11: =(('P&L to FCF'!$C$16/(1+$B11)^1+'P&L to FCF'!$D$16/(1+$B11)^2+'P&L to FCF'!$E$16/(1+$B11)^3+'P&L to FCF'!$F$16/(1+$B11)^4+'P&L to FCF'!$G$16/(1+$B11)^5+'P&L to FCF'!$G$16*(1+G$4)/($B11-G$4)/(1+$B11)^5)-Assumptions!$C$37)/Assumptions!$C$40/Assumptions!$C$38 -> 2.9229959

Sheet Monte Carlo
B1: MONTE CARLO SIMULATION
B2: Live engine. Every path below draws its own random inputs and runs a complete DCF in-row. Nothing is pasted in. Press F9 in Excel to re-run all 1,000 paths.
B4: DISTRIBUTION PARAMETERS
B5: Variable | C5: Shape | D5: Low | E5: Mode | F5: High
B6: WACC | C6: Triangular | D6: 0.085 | E6: 0.0963 | F6: 0.115
B7: Terminal growth | C7: Uniform | D7: 0.01 | E7: n/a | F7: 0.03
B8: Commercial growth | C8: Triangular | D8: 0.03 | E8: 0.06 | F8: 0.09
B10: UCL qualification probability by season (drawn as a coin flip each year)
B11: Year 1 | C11: Year 2 | D11: Year 3 | E11: Year 4 | F11: Year 5
B12: 1 | C12: =Assumptions!$C$18 -> 0.65 | D12: =Assumptions!$C$19 -> 0.6 | E12: =Assumptions!$C$20 -> 0.57 | F12: =Assumptions!$C$21 -> 0.55
B13: Year 1 is fixed at 100% because qualification is already confirmed.
B20: RESULTS
B21: Statistic | C21: Value
B22: Paths simulated | C22: =COUNT($V$53:$V$1052) -> 1000
B23: Mean value per share | C23: =AVERAGE($V$53:$V$1052) -> 2.6286115
B24: Median | C24: =MEDIAN($V$53:$V$1052) -> 3.5069249
B25: 10th percentile (bear) | C25: =PERCENTILE($V$53:$V$1052,0.1) -> -0.8204271
B26: 25th percentile | C26: =PERCENTILE($V$53:$V$1052,0.25) -> -0.22541681
B27: 75th percentile | C27: =PERCENTILE($V$53:$V$1052,0.75) -> 5.0246261
B28: 90th percentile (bull) | C28: =PERCENTILE($V$53:$V$1052,0.9) -> 6.0671664
B29: Standard deviation | C29: =STDEV($V$53:$V$1052) -> 2.7947722
B30: Market price | C30: =Assumptions!$C$39 -> 22.23
B31: % paths above market | C31: =COUNTIF($V$53:$V$1052,">"&Assumptions!$C$39)/COUNT($V$53:$V$1052) -> 0
B32: % paths equity wiped out | C32: =COUNTIF($V$53:$V$1052,"<0")/COUNT($V$53:$V$1052) -> 0.311
B34: DISTRIBUTION OF OUTCOMES
B35: Value per share | C35: Paths | D35: Share | E35: Histogram | G35: Wiped out | H35: Survives
B36: -3 to -2 | C36: =COUNTIFS($V$53:$V$1052,">=-3",$V$53:$V$1052,"<-2") -> 0 | D36: =C36/COUNT($V$53:$V$1052) -> 0 | E36: =REPT("█",ROUND(C36/MAX($C$36:$C$48)*26,0)) | G36: =C36 -> 0 | H36: 0
B37: -2 to -1 | C37: =COUNTIFS($V$53:$V$1052,">=-2",$V$53:$V$1052,"<-1") -> 71 | D37: =C37/COUNT($V$53:$V$1052) -> 0.071 | E37: =REPT("█",ROUND(C37/MAX($C$36:$C$48)*26,0)) -> ████████ | G37: =C37 -> 71 | H37: 0
B38: -1 to 0 | C38: =COUNTIFS($V$53:$V$1052,">=-1",$V$53:$V$1052,"<0") -> 240 | D38: =C38/COUNT($V$53:$V$1052) -> 0.24 | E38: =REPT("█",ROUND(C38/MAX($C$36:$C$48)*26,0)) -> ██████████████████████████ | G38: =C38 -> 240 | H38: 0
B39: 0 to 1 | C39: =COUNTIFS($V$53:$V$1052,">=0",$V$53:$V$1052,"<1") -> 113 | D39: =C39/COUNT($V$53:$V$1052) -> 0.113 | E39: =REPT("█",ROUND(C39/MAX($C$36:$C$48)*26,0)) -> ████████████ | G39: 0 | H39: =C39 -> 113
B40: 1 to 2 | C40: =COUNTIFS($V$53:$V$1052,">=1",$V$53:$V$1052,"<2") -> 14 | D40: =C40/COUNT($V$53:$V$1052) -> 0.014 | E40: =REPT("█",ROUND(C40/MAX($C$36:$C$48)*26,0)) -> ██ | G40: 0 | H40: =C40 -> 14
B41: 2 to 3 | C41: =COUNTIFS($V$53:$V$1052,">=2",$V$53:$V$1052,"<3") -> 17 | D41: =C41/COUNT($V$53:$V$1052) -> 0.017 | E41: =REPT("█",ROUND(C41/MAX($C$36:$C$48)*26,0)) -> ██ | G41: 0 | H41: =C41 -> 17
B42: 3 to 4 | C42: =COUNTIFS($V$53:$V$1052,">=3",$V$53:$V$1052,"<4") -> 116 | D42: =C42/COUNT($V$53:$V$1052) -> 0.116 | E42: =REPT("█",ROUND(C42/MAX($C$36:$C$48)*26,0)) -> █████████████ | G42: 0 | H42: =C42 -> 116
B43: 4 to 5 | C43: =COUNTIFS($V$53:$V$1052,">=4",$V$53:$V$1052,"<5") -> 175 | D43: =C43/COUNT($V$53:$V$1052) -> 0.175 | E43: =REPT("█",ROUND(C43/MAX($C$36:$C$48)*26,0)) -> ███████████████████ | G43: 0 | H43: =C43 -> 175
B44: 5 to 6 | C44: =COUNTIFS($V$53:$V$1052,">=5",$V$53:$V$1052,"<6") -> 142 | D44: =C44/COUNT($V$53:$V$1052) -> 0.142 | E44: =REPT("█",ROUND(C44/MAX($C$36:$C$48)*26,0)) -> ███████████████ | G44: 0 | H44: =C44 -> 142
B45: 6 to 7 | C45: =COUNTIFS($V$53:$V$1052,">=6",$V$53:$V$1052,"<7") -> 84 | D45: =C45/COUNT($V$53:$V$1052) -> 0.084 | E45: =REPT("█",ROUND(C45/MAX($C$36:$C$48)*26,0)) -> █████████ | G45: 0 | H45: =C45 -> 84
B46: 7 to 8 | C46: =COUNTIFS($V$53:$V$1052,">=7",$V$53:$V$1052,"<8") -> 23 | D46: =C46/COUNT($V$53:$V$1052) -> 0.023 | E46: =REPT("█",ROUND(C46/MAX($C$36:$C$48)*26,0)) -> ██ | G46: 0 | H46: =C46 -> 23
B47: 8 to 9 | C47: =COUNTIFS($V$53:$V$1052,">=8",$V$53:$V$1052,"<9") -> 5 | D47: =C47/COUNT($V$53:$V$1052) -> 0.005 | E47: =REPT("█",ROUND(C47/MAX($C$36:$C$48)*26,0)) -> █ | G47: 0 | H47: =C47 -> 5
B48: 9 to 10 | C48: =COUNTIFS($V$53:$V$1052,">=9",$V$53:$V$1052,"<10") -> 0 | D48: =C48/COUNT($V$53:$V$1052) -> 0 | E48: =REPT("█",ROUND(C48/MAX($C$36:$C$48)*26,0)) | G48: 0 | H48: =C48 -> 0
B49: Total | C49: =SUM(C36:C48) -> 1000 | D49: =SUM(D36:D48) -> 1
...
